Workbook

Sheet Original_Data
A1: store_id | B1: month | C1: region | D1: store_type | E1: marketing_spend | F1: footfall | G1: avg_discount_pct | H1: staff_count | I1: inventory_availability_pct | J1: competitor_distance_km | K1: holiday_flag | L1: customer_rating | M1: monthly_sales | N1: monthly_profit
A2: STR-1001 | B2: 45658 | C2: East | D2: Residential | E2: 70389.11 | F2: 8302 | G2: 0.042 | H2: 17 | I2: 75 | J2: 5.28 | K2: 1 | L2: 3.1 | M2: 658832.62 | N2: 84349.93
A3: STR-1001 | B3: 45689 | C3: East | D3: Residential | E3: 43827.89 | F3: 8487 | G3: 0.168 | H3: 23 | I3: 84.4 | J3: 4.31 | K3: 0 | L3: 2.8 | M3: 634436 | N3: 106130.54
A4: STR-1001 | B4: 45717 | C4: East | D4: Residential | E4: 59921.75 | F4: 9113 | G4: 0.133 | H4: 20 | I4: 88 | J4: 12 | K4: 0 | L4: 3.2 | M4: 678722.06 | N4: 101883.86
A5: STR-1001 | B5: 45748 | C5: East | D5: Residential | E5: 56856.63 | F5: 9431 | G5: 0.142 | H5: 23 | I5: 86.9 | J5: 4.97 | K5: 0 | L5: 3.4 | M5: 658920.3 | N5: 97910.37
A6: STR-1002 | B6: 45658 | C6: East | D6: High Street | E6: 48412.64 | F6: 9545 | G6: 0.231 | H6: 21 | I6: 97.6 | J6: 6.94 | K6: 1 | L6: 4.2 | M6: 741341.44 | N6: 119208.17
A7: STR-1002 | B7: 45689 | C7: East | D7: High Street | E7: 64811.21 | F7: 9792 | G7: 0.112 | H7: 20 | I7: 84.2 | J7: 2.88 | K7: 0 | L7: 4.2 | M7: 761835.34 | N7: 149602.23
A8: STR-1002 | B8: 45717 | C8: East | D8: High Street | E8: 46213.45 | F8: 10616 | G8: 0.122 | H8: 22 | I8: 85.2 | J8: 0.2 | K8: 1 | L8: 4.1 | M8: 806615.54 | N8: 131364.62
A9: STR-1002 | B9: 45748 | C9: East | D9: High Street | E9: 68148.52 | F9: 8567 | G9: 0.127 | H9: 23 | I9: 95.6 | J9: 0.8 | K9: 0 | L9: 3.9 | M9: 850164.26 | N9: 149262.75
A10: STR-1003 | B10: 45658 | C10: North | D10: Airport | E10: 71838.86 | F10: 10979 | G10: 0.215 | H10: 26 | I10: 88.6 | J10: 7.7 | K10: 1 | L10: 3.8 | M10: 930581.7 | N10: 136207.98
A11: STR-1003 | B11: 45689 | C11: North | D11: Airport | E11: 68133.44 | F11: 9459 | G11: 0.22 | H11: 21 | I11: 85 | J11: 1.91 | K11: 0 | L11: 4.2 | M11: 779010.94 | N11: 106328.09
A12: STR-1003 | B12: 45717 | C12: North | D12: Airport | E12: 34285.21 | F12: 9172 | G12: 0.213 | H12: 22 | I12: 88.3 | J12: 10.46 | K12: 1 | L12: 3.8 | M12: 723060.76 | N12: 123131.24
A13: STR-1003 | B13: 45748 | C13: North | D13: Airport | E13: 67979.88 | F13: 11230 | G13: 0.002 | H13: 28 | I13: 85.3 | J13: 7.16 | K13: 0 | L13: 3.8 | M13: 910791.94 | N13: 158891.28
... A34: STR-1009 | B34: 45658 | C34: North | D34: Residential | E34: 54597.83 | F34: 9429 | G34: 0.188 | H34: 21 | I34: 83.3 | J34: 11.71 | K34: 0 | L34: 4.2 | M34: 641865.03 | N34: 81342.58
A35: STR-1009 | B35: 45689 | C35: North | D35: Residential | E35: 73771.91 | F35: 11695 | G35: 0.07 | H35: 25 | I35: 84.7 | J35: 0.62 | K35: 0 | M35: 799477.76 | N35: 164974.41
A36: STR-1009 | B36: 45717 | C36: North | D36: Residential | E36: 74413.88 | F36: 9449 | G36: 0.039 | H36: 23 | I36: 92.1 | J36: 2.12 | K36: 0 | L36: 3.5 | M36: 798952.17 | N36: 161499.04
A37: STR-1009 | B37: 45748 | C37: North | D37: Residential | E37: 52483.77 | F37: 10453 | G37: 0.247 | H37: 25 | I37: 99 | J37: 6.31 | K37: 0 | L37: 3.6 | M37: 800979.78 | N37: 149242.27
A38: STR-1010 | B38: 45658 | C38: North | D38: Mall | E38: 75269.87 | F38: 8838 | G38: 0.092 | H38: 21 | I38: 83.1 | J38: 9.56 | K38: 1 | L38: 4.2 | M38: 820593.93 | N38: 115860.06
A39: STR-1010 | B39: 45689 | C39: North | D39: Mall | E39: 61245.41 | F39: 8156 | G39: 0.156 | H39: 19 | I39: 92.9 | J39: 9.05 | K39: 0 | L39: 3.8 | M39: 718330.53 | N39: 93247.9
A40: STR-1010 | B40: 45717 | C40: North | D40: Mall | E40: 93381.26 | F40: 7562 | G40: 0.198 | H40: 19 | I40: 82.9 | J40: 5.05 | K40: 0 | L40: 4 | M40: 736633.4 | N40: 115654.66
A41: STR-1010 | B41: 45748 | C41: North | D41: Mall | E41: 65012.19 | F41: 9598 | G41: 0.085 | H41: 24 | I41: 98.3 | J41: 0.89 | K41: 0 | L41: 3.8 | M41: 828623.85 | N41: 167320.52
A42: STR-1011 | B42: 45658 | C42: East | D42: Mall | E42: 40462.94 | F42: 3660 | G42: 0.218 | H42: 11 | I42: 95.2 | J42: 5.57 | K42: 0 | L42: 4.4 | M42: 592195.85 | N42: 92291.56
A43: STR-1011 | B43: 45689 | C43: East | D43: Mall | E43: 46123.88 | F43: 3227 | G43: 0.143 | H43: 10 | I43: 75.4 | J43: 1.06 | K43: 0 | L43: 4.4 | M43: 532644.46 | N43: 60681.32
A44: STR-1011 | B44: 45717 | C44: East | D44: Mall | E44: 68077.54 | F44: 3360 | G44: 0.128 | H44: 14 | I44: 88.2 | J44: 1.24 | K44: 1 | L44: 4 | M44: 657429.18 | N44: 88919.74
A45: STR-1011 | B45: 45748 | C45: East | D45: Mall | E45: 64882.14 | F45: 3642 | G45: 0.019 | H45: 13 | I45: 87.8 | J45: 4.52 | K45: 0 | L45: 4.2 | M45: 605178 | N45: 106958.74
A46: STR-1012 | B46: 45658 | C46: West | D46: Residential | E46: 138855.51 | F46: 5145 | G46: 0.06 | H46: 17 | I46: 88.2 | J46: 9.58 | K46: 0 | L46: 3.2 | M46: 595467.6 | N46: 104276.46
A47: STR-1012 | B47: 45689 | C47: West | D47: Residential | E47: 63630.21 | F47: 4460 | G47: 0.235 | H47: 14 | I47: 98.6 | J47: 5.52 | K47: 0 | L47: 3.5 | M47: 599603.4 | N47: 112685.12
... A72: STR-1018 | B72: 45717 | C72: East | D72: High Street | E72: 60571.82 | F72: 3193 | G72: 0.197 | H72: 7 | I72: 99 | J72: 1.43 | K72: 0 | L72: 3.2 | M72: 605023.87 | N72: 98545.81
A73: STR-1018 | B73: 45748 | C73: East | D73: High Street | E73: 55081.16 | F73: 5485 | G73: 0.036 | H73: 12 | I73: 88 | K73: 0 | L73: 3.5 | M73: 674774.09 | N73: 141917.59
A74: STR-1019 | B74: 45658 | C74: East | D74: Residential | E74: 46201.46 | F74: 5918 | G74: 0.277 | H74: 13 | I74: 78.8 | J74: 4.91 | K74: 0 | L74: 4.5 | M74: 616069.41 | N74: 54453.99
A75: STR-1019 | B75: 45689 | C75: East | D75: Residential | E75: 53762.92 | F75: 6821 | G75: 0.066 | H75: 19 | I75: 94.6 | J75: 7.03 | K75: 0 | L75: 4.4 | M75: 630829.94 | N75: 117090.02
A76: STR-1019 | B76: 45717 | C76: East | D76: Residential | E76: 70144.78 | F76: 6806 | G76: 0.178 | H76: 20 | I76: 93.1 | J76: 0.28 | K76: 1 | L76: 4.3 | M76: 788087.68 | N76: 116803.42
A77: STR-1019 | B77: 45748 | C77: East | D77: Residential | E77: 58749.63 | F77: 8252 | G77: 0.203 | H77: 20 | I77: 85.2 | J77: 3.61 | K77: 0 | L77: 4.5 | M77: 680840.36 | N77: 68007.68
A78: STR-1020 | B78: 45658 | C78: South | D78: High Street | E78: 56973.18 | F78: 6662 | G78: 0.1 | H78: 15 | I78: 77.7 | J78: 7.52 | K78: 1 | L78: 3.2 | M78: 643657.47 | N78: 87022.45
A79: STR-1020 | B79: 45689 | C79: South | D79: High Street | E79: 54872.82 | F79: 5962 | G79: 0.064 | H79: 12 | I79: 85.4 | J79: 2.58 | K79: 0 | L79: 2.9 | M79: 691112.6 | N79: 109212.83
A80: STR-1020 | B80: 45717 | C80: South | D80: High Street | E80: 80562.81 | F80: 7470 | G80: 0.172 | H80: 16 | I80: 83.5 | J80: 2.29 | K80: 0 | L80: 3.3 | M80: 776922.17 | N80: 150701.93
A81: STR-1020 | B81: 45748 | C81: South | D81: High Street | E81: 77999.9 | F81: 5974 | G81: 0.252 | H81: 14 | I81: 81.3 | J81: 2.39 | K81: 0 | L81: 3.2 | M81: 636561.34 | N81: 93861.06
A82: STR-1021 | B82: 45658 | C82: West | D82: Mall | E82: 60881.01 | F82: 5410 | G82: 0.179 | H82: 15 | I82: 83.9 | J82: 5.24 | K82: 0 | L82: 4.6 | M82: 621369.58 | N82: 85493.64
A83: STR-1021 | B83: 45689 | C83: West | D83: Mall | E83: 60628.38 | F83: 4451 | G83: 0.095 | H83: 10 | I83: 89.6 | J83: 3.17 | K83: 0 | L83: 4.6 | M83: 682208.01 | N83: 110318.84
A84: STR-1021 | B84: 45717 | C84: West | D84: Mall | E84: 72731.14 | F84: 4644 | G84: 0.084 | H84: 15 | I84: 87.1 | J84: 2.66 | K84: 0 | L84: 4.6 | M84: 727241.86 | N84: 155810.3
...

Sheet Cleaned_Data
A1: store_id | B1: month | C1: region | D1: store_type | E1: marketing_spend | F1: footfall | G1: avg_discount_pct | H1: staff_count | I1: inventory_availability_pct | J1: competitor_distance_km | K1: competitor_distance_km_cleaned | L1: holiday_flag | M1: customer_rating | N1: customer_rating_cleaned | O1: monthly_sales | P1: monthly_profit
A2: STR-1001 | B2: 45658 | C2: East | D2: Residential | E2: 70389.11 | F2: 8302 | G2: 0.042 | H2: 17 | I2: 75 | J2: 5.28 | K2: =IF(J2="",AVERAGE(J2:J321),J2) -> 5.28 | L2: 1 | M2: 3.1 | N2: =IF(M2="",AVERAGE(M2:M321),M2) -> 3.1 | O2: 658832.62 | P2: 84349.93
A3: STR-1001 | B3: 45689 | C3: East | D3: Residential | E3: 43827.89 | F3: 8487 | G3: 0.168 | H3: 23 | I3: 84.4 | J3: 4.31 | K3: =IF(J3="",AVERAGE(J3:J322),J3) -> 4.31 | L3: 0 | M3: 2.8 | N3: =IF(M3="",AVERAGE(M3:M322),M3) -> 2.8 | O3: 634436 | P3: 106130.54
A4: STR-1001 | B4: 45717 | C4: East | D4: Residential | E4: 59921.75 | F4: 9113 | G4: 0.133 | H4: 20 | I4: 88 | J4: 12 | K4: =IF(J4="",AVERAGE(J4:J323),J4) -> 12 | L4: 0 | M4: 3.2 | N4: =IF(M4="",AVERAGE(M4:M323),M4) -> 3.2 | O4: 678722.06 | P4: 101883.86
A5: STR-1001 | B5: 45748 | C5: East | D5: Residential | E5: 56856.63 | F5: 9431 | G5: 0.142 | H5: 23 | I5: 86.9 | J5: 4.97 | K5: =IF(J5="",AVERAGE(J5:J324),J5) -> 4.97 | L5: 0 | M5: 3.4 | N5: =IF(M5="",AVERAGE(M5:M324),M5) -> 3.4 | O5: 658920.3 | P5: 97910.37
A6: STR-1002 | B6: 45658 | C6: East | D6: High Street | E6: 48412.64 | F6: 9545 | G6: 0.231 | H6: 21 | I6: 97.6 | J6: 6.94 | K6: =IF(J6="",AVERAGE(J6:J325),J6) -> 6.94 | L6: 1 | M6: 4.2 | N6: =IF(M6="",AVERAGE(M6:M325),M6) -> 4.2 | O6: 741341.44 | P6: 119208.17
A7: STR-1002 | B7: 45689 | C7: East | D7: High Street | E7: 64811.21 | F7: 9792 | G7: 0.112 | H7: 20 | I7: 84.2 | J7: 2.88 | K7: =IF(J7="",AVERAGE(J7:J326),J7) -> 2.88 | L7: 0 | M7: 4.2 | N7: =IF(M7="",AVERAGE(M7:M326),M7) -> 4.2 | O7: 761835.34 | P7: 149602.23
A8: STR-1002 | B8: 45717 | C8: East | D8: High Street | E8: 46213.45 | F8: 10616 | G8: 0.122 | H8: 22 | I8: 85.2 | J8: 0.2 | K8: =IF(J8="",AVERAGE(J8:J327),J8) -> 0.2 | L8: 1 | M8: 4.1 | N8: =IF(M8="",AVERAGE(M8:M327),M8) -> 4.1 | O8: 806615.54 | P8: 131364.62
A9: STR-1002 | B9: 45748 | C9: East | D9: High Street | E9: 68148.52 | F9: 8567 | G9: 0.127 | H9: 23 | I9: 95.6 | J9: 0.8 | K9: =IF(J9="",AVERAGE(J9:J328),J9) -> 0.8 | L9: 0 | M9: 3.9 | N9: =IF(M9="",AVERAGE(M9:M328),M9) -> 3.9 | O9: 850164.26 | P9: 149262.75
A10: STR-1003 | B10: 45658 | C10: North | D10: Airport | E10: 71838.86 | F10: 10979 | G10: 0.215 | H10: 26 | I10: 88.6 | J10: 7.7 | K10: =IF(J10="",AVERAGE(J10:J329),J10) -> 7.7 | L10: 1 | M10: 3.8 | N10: =IF(M10="",AVERAGE(M10:M329),M10) -> 3.8 | O10: 930581.7 | P10: 136207.98
A11: STR-1003 | B11: 45689 | C11: North | D11: Airport | E11: 68133.44 | F11: 9459 | G11: 0.22 | H11: 21 | I11: 85 | J11: 1.91 | K11: =IF(J11="",AVERAGE(J11:J330),J11) -> 1.91 | L11: 0 | M11: 4.2 | N11: =IF(M11="",AVERAGE(M11:M330),M11) -> 4.2 | O11: 779010.94 | P11: 106328.09
A12: STR-1003 | B12: 45717 | C12: North | D12: Airport | E12: 34285.21 | F12: 9172 | G12: 0.213 | H12: 22 | I12: 88.3 | J12: 10.46 | K12: =IF(J12="",AVERAGE(J12:J331),J12) -> 10.46 | L12: 1 | M12: 3.8 | N12: =IF(M12="",AVERAGE(M12:M331),M12) -> 3.8 | O12: 723060.76 | P12: 123131.24
A13: STR-1003 | B13: 45748 | C13: North | D13: Airport | E13: 67979.88 | F13: 11230 | G13: 0.002 | H13: 28 | I13: 85.3 | J13: 7.16 | K13: =IF(J13="",AVERAGE(J13:J332),J13) -> 7.16 | L13: 0 | M13: 3.8 | N13: =IF(M13="",AVERAGE(M13:M332),M13) -> 3.8 | O13: 910791.94 | P13: 158891.28
... A34: STR-1009 | B34: 45658 | C34: North | D34: Residential | E34: 54597.83 | F34: 9429 | G34: 0.188 | H34: 21 | I34: 83.3 | J34: 11.71 | K34: =IF(J34="",AVERAGE(J34:J353),J34) -> 11.71 | L34: 0 | M34: 4.2 | N34: =IF(M34="",AVERAGE(M34:M353),M34) -> 4.2 | O34: 641865.03 | P34: 81342.58
A35: STR-1009 | B35: 45689 | C35: North | D35: Residential | E35: 73771.91 | F35: 11695 | G35: 0.07 | H35: 25 | I35: 84.7 | J35: 0.62 | K35: =IF(J35="",AVERAGE(J35:J354),J35) -> 0.62 | L35: 0 | N35: =IF(M35="",AVERAGE(M35:M354),M35) -> 3.9243728 | O35: 799477.76 | P35: 164974.41
A36: STR-1009 | B36: 45717 | C36: North | D36: Residential | E36: 74413.88 | F36: 9449 | G36: 0.039 | H36: 23 | I36: 92.1 | J36: 2.12 | K36: =IF(J36="",AVERAGE(J36:J355),J36) -> 2.12 | L36: 0 | M36: 3.5 | N36: =IF(M36="",AVERAGE(M36:M355),M36) -> 3.5 | O36: 798952.17 | P36: 161499.04
A37: STR-1009 | B37: 45748 | C37: North | D37: Residential | E37: 52483.77 | F37: 10453 | G37: 0.247 | H37: 25 | I37: 99 | J37: 6.31 | K37: =IF(J37="",AVERAGE(J37:J356),J37) -> 6.31 | L37: 0 | M37: 3.6 | N37: =IF(M37="",AVERAGE(M37:M356),M37) -> 3.6 | O37: 800979.78 | P37: 149242.27
A38: STR-1010 | B38: 45658 | C38: North | D38: Mall | E38: 75269.87 | F38: 8838 | G38: 0.092 | H38: 21 | I38: 83.1 | J38: 9.56 | K38: =IF(J38="",AVERAGE(J38:J357),J38) -> 9.56 | L38: 1 | M38: 4.2 | N38: =IF(M38="",AVERAGE(M38:M357),M38) -> 4.2 | O38: 820593.93 | P38: 115860.06
A39: STR-1010 | B39: 45689 | C39: North | D39: Mall | E39: 61245.41 | F39: 8156 | G39: 0.156 | H39: 19 | I39: 92.9 | J39: 9.05 | K39: =IF(J39="",AVERAGE(J39:J358),J39) -> 9.05 | L39: 0 | M39: 3.8 | N39: =IF(M39="",AVERAGE(M39:M358),M39) -> 3.8 | O39: 718330.53 | P39: 93247.9
A40: STR-1010 | B40: 45717 | C40: North | D40: Mall | E40: 93381.26 | F40: 7562 | G40: 0.198 | H40: 19 | I40: 82.9 | J40: 5.05 | K40: =IF(J40="",AVERAGE(J40:J359),J40) -> 5.05 | L40: 0 | M40: 4 | N40: =IF(M40="",AVERAGE(M40:M359),M40) -> 4 | O40: 736633.4 | P40: 115654.66
A41: STR-1010 | B41: 45748 | C41: North | D41: Mall | E41: 65012.19 | F41: 9598 | G41: 0.085 | H41: 24 | I41: 98.3 | J41: 0.89 | K41: =IF(J41="",AVERAGE(J41:J360),J41) -> 0.89 | L41: 0 | M41: 3.8 | N41: =IF(M41="",AVERAGE(M41:M360),M41) -> 3.8 | O41: 828623.85 | P41: 167320.52
A42: STR-1011 | B42: 45658 | C42: East | D42: Mall | E42: 40462.94 | F42: 3660 | G42: 0.218 | H42: 11 | I42: 95.2 | J42: 5.57 | K42: =IF(J42="",AVERAGE(J42:J361),J42) -> 5.57 | L42: 0 | M42: 4.4 | N42: =IF(M42="",AVERAGE(M42:M361),M42) -> 4.4 | O42: 592195.85 | P42: 92291.56
A43: STR-1011 | B43: 45689 | C43: East | D43: Mall | E43: 46123.88 | F43: 3227 | G43: 0.143 | H43: 10 | I43: 75.4 | J43: 1.06 | K43: =IF(J43="",AVERAGE(J43:J362),J43) -> 1.06 | L43: 0 | M43: 4.4 | N43: =IF(M43="",AVERAGE(M43:M362),M43) -> 4.4 | O43: 532644.46 | P43: 60681.32
A44: STR-1011 | B44: 45717 | C44: East | D44: Mall | E44: 68077.54 | F44: 3360 | G44: 0.128 | H44: 14 | I44: 88.2 | J44: 1.24 | K44: =IF(J44="",AVERAGE(J44:J363),J44) -> 1.24 | L44: 1 | M44: 4 | N44: =IF(M44="",AVERAGE(M44:M363),M44) -> 4 | O44: 657429.18 | P44: 88919.74
A45: STR-1011 | B45: 45748 | C45: East | D45: Mall | E45: 64882.14 | F45: 3642 | G45: 0.019 | H45: 13 | I45: 87.8 | J45: 4.52 | K45: =IF(J45="",AVERAGE(J45:J364),J45) -> 4.52 | L45: 0 | M45: 4.2 | N45: =IF(M45="",AVERAGE(M45:M364),M45) -> 4.2 | O45: 605178 | P45: 106958.74
A46: STR-1012 | B46: 45658 | C46: West | D46: Residential | E46: 138855.51 | F46: 5145 | G46: 0.06 | H46: 17 | I46: 88.2 | J46: 9.58 | K46: =IF(J46="",AVERAGE(J46:J365),J46) -> 9.58 | L46: 0 | M46: 3.2 | N46: =IF(M46="",AVERAGE(M46:M365),M46) -> 3.2 | O46: 595467.6 | P46: 104276.46
A47: STR-1012 | B47: 45689 | C47: West | D47: Residential | E47: 63630.21 | F47: 4460 | G47: 0.235 | H47: 14 | I47: 98.6 | J47: 5.52 | K47: =IF(J47="",AVERAGE(J47:J366),J47) -> 5.52 | L47: 0 | M47: 3.5 | N47: =IF(M47="",AVERAGE(M47:M366),M47) -> 3.5 | O47: 599603.4 | P47: 112685.12
... A72: STR-1018 | B72: 45717 | C72: East | D72: High Street | E72: 60571.82 | F72: 3193 | G72: 0.197 | H72: 7 | I72: 99 | J72: 1.43 | K72: =IF(J72="",AVERAGE(J72:J391),J72) -> 1.43 | L72: 0 | M72: 3.2 | N72: =IF(M72="",AVERAGE(M72:M391),M72) -> 3.2 | O72: 605023.87 | P72: 98545.81
A73: STR-1018 | B73: 45748 | C73: East | D73: High Street | E73: 55081.16 | F73: 5485 | G73: 0.036 | H73: 12 | I73: 88 | K73: =IF(J73="",AVERAGE(J73:J392),J73) -> 4.4552263 | L73: 0 | M73: 3.5 | N73: =IF(M73="",AVERAGE(M73:M392),M73) -> 3.5 | O73: 674774.09 | P73: 141917.59
A74: STR-1019 | B74: 45658 | C74: East | D74: Residential | E74: 46201.46 | F74: 5918 | G74: 0.277 | H74: 13 | I74: 78.8 | J74: 4.91 | K74: =IF(J74="",AVERAGE(J74:J393),J74) -> 4.91 | L74: 0 | M74: 4.5 | N74: =IF(M74="",AVERAGE(M74:M393),M74) -> 4.5 | O74: 616069.41 | P74: 54453.99
A75: STR-1019 | B75: 45689 | C75: East | D75: Residential | E75: 53762.92 | F75: 6821 | G75: 0.066 | H75: 19 | I75: 94.6 | J75: 7.03 | K75: =IF(J75="",AVERAGE(J75:J394),J75) -> 7.03 | L75: 0 | M75: 4.4 | N75: =IF(M75="",AVERAGE(M75:M394),M75) -> 4.4 | O75: 630829.94 | P75: 117090.02
A76: STR-1019 | B76: 45717 | C76: East | D76: Residential | E76: 70144.78 | F76: 6806 | G76: 0.178 | H76: 20 | I76: 93.1 | J76: 0.28 | K76: =IF(J76="",AVERAGE(J76:J395),J76) -> 0.28 | L76: 1 | M76: 4.3 | N76: =IF(M76="",AVERAGE(M76:M395),M76) -> 4.3 | O76: 788087.68 | P76: 116803.42
A77: STR-1019 | B77: 45748 | C77: East | D77: Residential | E77: 58749.63 | F77: 8252 | G77: 0.203 | H77: 20 | I77: 85.2 | J77: 3.61 | K77: =IF(J77="",AVERAGE(J77:J396),J77) -> 3.61 | L77: 0 | M77: 4.5 | N77: =IF(M77="",AVERAGE(M77:M396),M77) -> 4.5 | O77: 680840.36 | P77: 68007.68
A78: STR-1020 | B78: 45658 | C78: South | D78: High Street | E78: 56973.18 | F78: 6662 | G78: 0.1 | H78: 15 | I78: 77.7 | J78: 7.52 | K78: =IF(J78="",AVERAGE(J78:J397),J78) -> 7.52 | L78: 1 | M78: 3.2 | N78: =IF(M78="",AVERAGE(M78:M397),M78) -> 3.2 | O78: 643657.47 | P78: 87022.45
A79: STR-1020 | B79: 45689 | C79: South | D79: High Street | E79: 54872.82 | F79: 5962 | G79: 0.064 | H79: 12 | I79: 85.4 | J79: 2.58 | K79: =IF(J79="",AVERAGE(J79:J398),J79) -> 2.58 | L79: 0 | M79: 2.9 | N79: =IF(M79="",AVERAGE(M79:M398),M79) -> 2.9 | O79: 691112.6 | P79: 109212.83
A80: STR-1020 | B80: 45717 | C80: South | D80: High Street | E80: 80562.81 | F80: 7470 | G80: 0.172 | H80: 16 | I80: 83.5 | J80: 2.29 | K80: =IF(J80="",AVERAGE(J80:J399),J80) -> 2.29 | L80: 0 | M80: 3.3 | N80: =IF(M80="",AVERAGE(M80:M399),M80) -> 3.3 | O80: 776922.17 | P80: 150701.93
A81: STR-1020 | B81: 45748 | C81: South | D81: High Street | E81: 77999.9 | F81: 5974 | G81: 0.252 | H81: 14 | I81: 81.3 | J81: 2.39 | K81: =IF(J81="",AVERAGE(J81:J400),J81) -> 2.39 | L81: 0 | M81: 3.2 | N81: =IF(M81="",AVERAGE(M81:M400),M81) -> 3.2 | O81: 636561.34 | P81: 93861.06
A82: STR-1021 | B82: 45658 | C82: West | D82: Mall | E82: 60881.01 | F82: 5410 | G82: 0.179 | H82: 15 | I82: 83.9 | J82: 5.24 | K82: =IF(J82="",AVERAGE(J82:J401),J82) -> 5.24 | L82: 0 | M82: 4.6 | N82: =IF(M82="",AVERAGE(M82:M401),M82) -> 4.6 | O82: 621369.58 | P82: 85493.64
A83: STR-1021 | B83: 45689 | C83: West | D83: Mall | E83: 60628.38 | F83: 4451 | G83: 0.095 | H83: 10 | I83: 89.6 | J83: 3.17 | K83: =IF(J83="",AVERAGE(J83:J402),J83) -> 3.17 | L83: 0 | M83: 4.6 | N83: =IF(M83="",AVERAGE(M83:M402),M83) -> 4.6 | O83: 682208.01 | P83: 110318.84
A84: STR-1021 | B84: 45717 | C84: West | D84: Mall | E84: 72731.14 | F84: 4644 | G84: 0.084 | H84: 15 | I84: 87.1 | J84: 2.66 | K84: =IF(J84="",AVERAGE(J84:J403),J84) -> 2.66 | L84: 0 | M84: 4.6 | N84: =IF(M84="",AVERAGE(M84:M403),M84) -> 4.6 | O84: 727241.86 | P84: 155810.3
...

Sheet  Dummy_Variables
A1: DUMMY VARIABLES FOR REGION CATEGORY | D1: DUMMY VARIABLES FOR STORE_TYPE CATEGORY
A2: Region_North | B2: Region_South | C2: Region_East | D2: Store_Airport | E2: Store_HighStreet | F2: Store_Residential
A3: =IF(Cleaned_Data!C2="North",1,0) -> 0 | B3: =IF(Cleaned_Data!C2="South",1,0) -> 0 | C3: =IF(Cleaned_Data!C2="East",1,0) -> 1 | D3: =IF(Cleaned_Data!D2="Airport",1,0) -> 0 | E3: =IF(Cleaned_Data!D2="High Street",1,0) -> 0 | F3: =IF(Cleaned_Data!D2="Residential",1,0) -> 1 | H3: Dummy Variable Notes
A4: =IF(Cleaned_Data!C3="North",1,0) -> 0 | B4: =IF(Cleaned_Data!C3="South",1,0) -> 0 | C4: =IF(Cleaned_Data!C3="East",1,0) -> 1 | D4: =IF(Cleaned_Data!D3="Airport",1,0) -> 0 | E4: =IF(Cleaned_Data!D3="High Street",1,0) -> 0 | F4: =IF(Cleaned_Data!D3="Residential",1,0) -> 1 | H4: Region Reference Category | I4: West
A5: =IF(Cleaned_Data!C4="North",1,0) -> 0 | B5: =IF(Cleaned_Data!C4="South",1,0) -> 0 | C5: =IF(Cleaned_Data!C4="East",1,0) -> 1 | D5: =IF(Cleaned_Data!D4="Airport",1,0) -> 0 | E5: =IF(Cleaned_Data!D4="High Street",1,0) -> 0 | F5: =IF(Cleaned_Data!D4="Residential",1,0) -> 1 | H5: Store Type Reference Category | I5: Mall
A6: =IF(Cleaned_Data!C5="North",1,0) -> 0 | B6: =IF(Cleaned_Data!C5="South",1,0) -> 0 | C6: =IF(Cleaned_Data!C5="East",1,0) -> 1 | D6: =IF(Cleaned_Data!D5="Airport",1,0) -> 0 | E6: =IF(Cleaned_Data!D5="High Street",1,0) -> 0 | F6: =IF(Cleaned_Data!D5="Residential",1,0) -> 1
A7: =IF(Cleaned_Data!C6="North",1,0) -> 0 | B7: =IF(Cleaned_Data!C6="South",1,0) -> 0 | C7: =IF(Cleaned_Data!C6="East",1,0) -> 1 | D7: =IF(Cleaned_Data!D6="Airport",1,0) -> 0 | E7: =IF(Cleaned_Data!D6="High Street",1,0) -> 1 | F7: =IF(Cleaned_Data!D6="Residential",1,0) -> 0
A8: =IF(Cleaned_Data!C7="North",1,0) -> 0 | B8: =IF(Cleaned_Data!C7="South",1,0) -> 0 | C8: =IF(Cleaned_Data!C7="East",1,0) -> 1 | D8: =IF(Cleaned_Data!D7="Airport",1,0) -> 0 | E8: =IF(Cleaned_Data!D7="High Street",1,0) -> 1 | F8: =IF(Cleaned_Data!D7="Residential",1,0) -> 0
A9: =IF(Cleaned_Data!C8="North",1,0) -> 0 | B9: =IF(Cleaned_Data!C8="South",1,0) -> 0 | C9: =IF(Cleaned_Data!C8="East",1,0) -> 1 | D9: =IF(Cleaned_Data!D8="Airport",1,0) -> 0 | E9: =IF(Cleaned_Data!D8="High Street",1,0) -> 1 | F9: =IF(Cleaned_Data!D8="Residential",1,0) -> 0
A10: =IF(Cleaned_Data!C9="North",1,0) -> 0 | B10: =IF(Cleaned_Data!C9="South",1,0) -> 0 | C10: =IF(Cleaned_Data!C9="East",1,0) -> 1 | D10: =IF(Cleaned_Data!D9="Airport",1,0) -> 0 | E10: =IF(Cleaned_Data!D9="High Street",1,0) -> 1 | F10: =IF(Cleaned_Data!D9="Residential",1,0) -> 0
A11: =IF(Cleaned_Data!C10="North",1,0) -> 1 | B11: =IF(Cleaned_Data!C10="South",1,0) -> 0 | C11: =IF(Cleaned_Data!C10="East",1,0) -> 0 | D11: =IF(Cleaned_Data!D10="Airport",1,0) -> 1 | E11: =IF(Cleaned_Data!D10="High Street",1,0) -> 0 | F11: =IF(Cleaned_Data!D10="Residential",1,0) -> 0
A12: =IF(Cleaned_Data!C11="North",1,0) -> 1 | B12: =IF(Cleaned_Data!C11="South",1,0) -> 0 | C12: =IF(Cleaned_Data!C11="East",1,0) -> 0 | D12: =IF(Cleaned_Data!D11="Airport",1,0) -> 1 | E12: =IF(Cleaned_Data!D11="High Street",1,0) -> 0 | F12: =IF(Cleaned_Data!D11="Residential",1,0) -> 0
A13: =IF(Cleaned_Data!C12="North",1,0) -> 1 | B13: =IF(Cleaned_Data!C12="South",1,0) -> 0 | C13: =IF(Cleaned_Data!C12="East",1,0) -> 0 | D13: =IF(Cleaned_Data!D12="Airport",1,0) -> 1 | E13: =IF(Cleaned_Data!D12="High Street",1,0) -> 0 | F13: =IF(Cleaned_Data!D12="Residential",1,0) -> 0
A14: =IF(Cleaned_Data!C13="North",1,0) -> 1 | B14: =IF(Cleaned_Data!C13="South",1,0) -> 0 | C14: =IF(Cleaned_Data!C13="East",1,0) -> 0 | D14: =IF(Cleaned_Data!D13="Airport",1,0) -> 1 | E14: =IF(Cleaned_Data!D13="High Street",1,0) -> 0 | F14: =IF(Cleaned_Data!D13="Residential",1,0) -> 0
A15: =IF(Cleaned_Data!C14="North",1,0) -> 0 | B15: =IF(Cleaned_Data!C14="South",1,0) -> 0 | C15: =IF(Cleaned_Data!C14="East",1,0) -> 1 | D15: =IF(Cleaned_Data!D14="Airport",1,0) -> 0 | E15: =IF(Cleaned_Data!D14="High Street",1,0) -> 0 | F15: =IF(Cleaned_Data!D14="Residential",1,0) -> 1
A16: =IF(Cleaned_Data!C15="North",1,0) -> 0 | B16: =IF(Cleaned_Data!C15="South",1,0) -> 0 | C16: =IF(Cleaned_Data!C15="East",1,0) -> 1 | D16: =IF(Cleaned_Data!D15="Airport",1,0) -> 0 | E16: =IF(Cleaned_Data!D15="High Street",1,0) -> 0 | F16: =IF(Cleaned_Data!D15="Residential",1,0) -> 1
A17: =IF(Cleaned_Data!C16="North",1,0) -> 0 | B17: =IF(Cleaned_Data!C16="South",1,0) -> 0 | C17: =IF(Cleaned_Data!C16="East",1,0) -> 1 | D17: =IF(Cleaned_Data!D16="Airport",1,0) -> 0 | E17: =IF(Cleaned_Data!D16="High Street",1,0) -> 0 | F17: =IF(Cleaned_Data!D16="Residential",1,0) -> 1
... A322: =IF(Cleaned_Data!C321="North",1,0) -> 0 | B322: =IF(Cleaned_Data!C321="South",1,0) -> 0 | C322: =IF(Cleaned_Data!C321="East",1,0) -> 1 | D322: =IF(Cleaned_Data!D321="Airport",1,0) -> 0 | E322: =IF(Cleaned_Data!D321="High Street",1,0) -> 0 | F322: =IF(Cleaned_Data!D321="Residential",1,0) -> 1

Sheet Simple_Regression
A1: SIMPLE REGRESSION MODEL 1
A2: Dependent Variable | B2: monthly_sales
A3: Independent Variable | B3: marketing_spend
A5: SUMMARY OUTPUT
A7: Regression Statistics
A8: Multiple R | B8: 0.40895561
A9: R Square | B9: 0.16724469
A10: Adjusted R Square | B10: 0.16462596
A11: Standard Error | B11: 94846.034
A12: Observations | B12: 320
A14: ANOVA
B15: df | C15: SS | D15: MS | E15: F | F15: Significance F
A16: Regression | B16: 1 | C16: 5.7451371e+11 | D16: 5.7451371e+11 | E16: 63.864873 | F16: 2.4800615e-14
A17: Residual | B17: 318 | C17: 2.8606549e+12 | D17: 8.9957701e+09
A18: Total | B18: 319 | C18: 3.4351686e+12
B20: Coefficients | C20: Standard Error | D20: t Stat | E20: P-value | F20: Lower 95% | G20: Upper 95% | H20: Lower 95.0% | I20: Upper 95.0%
A21: Intercept | B21: 560777.35 | C21: 15906.906 | D21: 35.253703 | E21: 6.9528769e-112 | F21: 529481.27 | G21: 592073.42 | H21: 529481.27 | I21: 592073.42
A22: marketing_spend | B22: 2.1295753 | C22: 0.26647838 | D22: 7.9915501 | E22: 2.4800615e-14 | F22: 1.6052919 | G22: 2.6538587 | H22: 1.6052919 | I22: 2.6538587
A27: SIMPLE REGRESSION MODEL 2
A28: Dependent Variable | B28: Monthly_Sales
A29: Independent Variable | B29: Footfall
A32: SUMMARY OUTPUT
A34: Regression Statistics
A35: Multiple R | B35: 0.85807071
A36: R Square | B36: 0.73628534
A37: Adjusted R Square | B37: 0.73545605
A38: Standard Error | B38: 53373.736
A39: Observations | B39: 320
A41: ANOVA
B42: df | C42: SS | D42: MS | E42: F | F42: Significance F
A43: Regression | B43: 1 | C43: 2.5292643e+12 | D43: 2.5292643e+12 | E43: 887.84878 | F43: 4.7503615e-94
A44: Residual | B44: 318 | C44: 9.0590432e+11 | D44: 2.8487557e+09
A45: Total | B45: 319 | C45: 3.4351686e+12
B47: Coefficients | C47: Standard Error | D47: t Stat | E47: P-value | F47: Lower 95% | G47: Upper 95% | H47: Lower 95.0% | I47: Upper 95.0%
A48: Intercept | B48: 446410.58 | C48: 8407.7383 | D48: 53.095205 | E48: 4.0862696e-160 | F48: 429868.76 | G48: 462952.4 | H48: 429868.76 | I48: 462952.4
A49: footfall | B49: 35.678031 | C49: 1.1973783 | D49: 29.796791 | E49: 4.7503615e-94 | F49: 33.322247 | G49: 38.033815 | H49: 33.322247 | I49: 38.033815

Sheet Multiple_Regression
A1: MULTIPLE REGRESSION
A2: monthly_sales | B2: marketing_spend | C2: footfall | D2: inventory_availability_pct | E2: Region_North | F2: Region_South | G2: Region_East | H2: Store_Airport | I2: Store_HighStreet | J2: Store_Residential | M2: SUMMARY OUTPUT
A3: 658832.62 | B3: 70389.11 | C3: 8302 | D3: 75 | E3: 0 | F3: 0 | G3: 1 | H3: 0 | I3: 0 | J3: 1
A4: 634436 | B4: 43827.89 | C4: 8487 | D4: 84.4 | E4: 0 | F4: 0 | G4: 1 | H4: 0 | I4: 0 | J4: 1 | M4: Regression Statistics
A5: 678722.06 | B5: 59921.75 | C5: 9113 | D5: 88 | E5: 0 | F5: 0 | G5: 1 | H5: 0 | I5: 0 | J5: 1 | M5: Multiple R | N5: 0.90930002
A6: 658920.3 | B6: 56856.63 | C6: 9431 | D6: 86.9 | E6: 0 | F6: 0 | G6: 1 | H6: 0 | I6: 0 | J6: 1 | M6: R Square | N6: 0.82682653
A7: 741341.44 | B7: 48412.64 | C7: 9545 | D7: 97.6 | E7: 0 | F7: 0 | G7: 1 | H7: 0 | I7: 1 | J7: 0 | M7: Adjusted R Square | N7: 0.82179891
A8: 761835.34 | B8: 64811.21 | C8: 9792 | D8: 84.2 | E8: 0 | F8: 0 | G8: 1 | H8: 0 | I8: 1 | J8: 0 | M8: Standard Error | N8: 43806.026
A9: 806615.54 | B9: 46213.45 | C9: 10616 | D9: 85.2 | E9: 0 | F9: 0 | G9: 1 | H9: 0 | I9: 1 | J9: 0 | M9: Observations | N9: 320
A10: 850164.26 | B10: 68148.52 | C10: 8567 | D10: 95.6 | E10: 0 | F10: 0 | G10: 1 | H10: 0 | I10: 1 | J10: 0
A11: 930581.7 | B11: 71838.86 | C11: 10979 | D11: 88.6 | E11: 1 | F11: 0 | G11: 0 | H11: 1 | I11: 0 | J11: 0 | M11: ANOVA
A12: 779010.94 | B12: 68133.44 | C12: 9459 | D12: 85 | E12: 1 | F12: 0 | G12: 0 | H12: 1 | I12: 0 | J12: 0 | N12: df | O12: SS | P12: MS | Q12: F | R12: Significance F
A13: 723060.76 | B13: 34285.21 | C13: 9172 | D13: 88.3 | E13: 1 | F13: 0 | G13: 0 | H13: 1 | I13: 0 | J13: 0 | M13: Regression | N13: 9 | O13: 2.8402886e+12 | P13: 3.1558762e+11 | Q13: 164.45695 | R13: 1.995252e-112
A14: 910791.94 | B14: 67979.88 | C14: 11230 | D14: 85.3 | E14: 1 | F14: 0 | G14: 0 | H14: 1 | I14: 0 | J14: 0 | M14: Residual | N14: 310 | O14: 5.9488007e+11 | P14: 1.918968e+09
A15: 922168.6 | B15: 71828.26 | C15: 12775 | D15: 81.7 | E15: 0 | F15: 0 | G15: 1 | H15: 0 | I15: 0 | J15: 1 | M15: Total | N15: 319 | O15: 3.4351686e+12
A16: 726606.28 | B16: 55716.82 | C16: 10054 | D16: 84.9 | E16: 0 | F16: 0 | G16: 1 | H16: 0 | I16: 0 | J16: 1
A17: 746501.09 | B17: 59909.51 | C17: 8895 | D17: 88.8 | E17: 0 | F17: 0 | G17: 1 | H17: 0 | I17: 0 | J17: 1 | N17: Coefficients | O17: Standard Error | P17: t Stat | Q17: P-value | R17: Lower 95% | S17: Upper 95% | T17: Lower 95.0% | U17: Upper 95.0%
A18: 834017.02 | B18: 75305.71 | C18: 10940 | D18: 76.5 | E18: 0 | F18: 0 | G18: 1 | H18: 0 | I18: 0 | J18: 1 | M18: Intercept | N18: 150574.38 | O18: 42373.194 | P18: 3.5535292 | Q18: 0.00043927018 | R18: 67198.938 | S18: 233949.82 | T18: 67198.938 | U18: 233949.82
A19: 666152.52 | B19: 48804.22 | C19: 7057 | D19: 87.7 | E19: 0 | F19: 1 | G19: 0 | H19: 0 | I19: 0 | J19: 1 | M19: marketing_spend | N19: 1.188358 | O19: 0.12683057 | P19: 9.3696493 | Q19: 1.5627412e-18 | R19: 0.9388003 | S19: 1.4379156 | T19: 0.9388003 | U19: 1.4379156
A20: 573155.19 | B20: 59117.9 | C20: 4263 | D20: 87.6 | E20: 0 | F20: 1 | G20: 0 | H20: 0 | I20: 0 | J20: 1 | M20: footfall | N20: 33.859813 | O20: 1.0245698 | P20: 33.047835 | Q20: 1.3099041e-103 | R20: 31.843822 | S20: 35.875804 | T20: 31.843822 | U20: 35.875804
A21: 666573.2 | B21: 78831.12 | C21: 5538 | D21: 94.1 | E21: 0 | F21: 1 | G21: 0 | H21: 0 | I21: 0 | J21: 1 | M21: inventory_availability_pct | N21: 2961.2706 | O21: 461.15508 | P21: 6.4214205 | Q21: 5.0658092e-10 | R21: 2053.8807 | S21: 3868.6606 | T21: 2053.8807 | U21: 3868.6606
A22: 591619.95 | B22: 41441.93 | C22: 4865 | D22: 88.3 | E22: 0 | F22: 1 | G22: 0 | H22: 0 | I22: 0 | J22: 1 | M22: Region_North | N22: -10576.286 | O22: 7214.2161 | P22: -1.466034 | Q22: 0.14365261 | R22: -24771.309 | S22: 3618.7368 | T22: -24771.309 | U22: 3618.7368
A23: 415721.82 | B23: 30356.28 | C23: 2822 | D23: 84.8 | E23: 1 | F23: 0 | G23: 0 | H23: 0 | I23: 0 | J23: 1 | M23: Region_South | N23: 1313.3957 | O23: 7324.4759 | P23: 0.179316 | Q23: 0.85780673 | R23: -13098.579 | S23: 15725.371 | T23: -13098.579 | U23: 15725.371
A24: 491905.13 | B24: 33518.88 | C24: 2121 | D24: 88.5 | E24: 1 | F24: 0 | G24: 0 | H24: 0 | I24: 0 | J24: 1 | M24: Region_East | N24: -18934.817 | O24: 6320.2241 | P24: -2.9959092 | Q24: 0.0029570732 | R24: -31370.781 | S24: -6498.8543 | T24: -31370.781 | U24: -6498.8543
A25: 555929.4 | B25: 42267.37 | C25: 3364 | D25: 82 | E25: 1 | F25: 0 | G25: 0 | H25: 0 | I25: 0 | J25: 1 | M25: Store_Airport | N25: 10756.801 | O25: 9733.0297 | P25: 1.1051852 | Q25: 0.26993635 | R25: -8394.3556 | S25: 29907.957 | T25: -8394.3556 | U25: 29907.957
A26: 565810.99 | B26: 62060.43 | C26: 2613 | D26: 92.1 | E26: 1 | F26: 0 | G26: 0 | H26: 0 | I26: 0 | J26: 1 | M26: Store_HighStreet | N26: -12295.387 | O26: 6551.5974 | P26: -1.8767006 | Q26: 0.061498317 | R26: -25186.611 | S26: 595.83685 | T26: -25186.611 | U26: 595.83685
A27: 811771.14 | B27: 57696.69 | C27: 10218 | D27: 94.8 | E27: 0 | F27: 0 | G27: 0 | H27: 0 | I27: 0 | J27: 0 | M27: Store_Residential | N27: -28871.871 | O27: 6690.572 | P27: -4.3153068 | Q27: 2.1461503e-05 | R27: -42036.548 | S27: -15707.194 | T27: -42036.548 | U27: -15707.194
A28: 800451.94 | B28: 172415.52 | C28: 8927 | D28: 86.2 | E28: 0 | F28: 0 | G28: 0 | H28: 0 | I28: 0 | J28: 0
A29: 783672.82 | B29: 55270.52 | C29: 9315 | D29: 91.9 | E29: 0 | F29: 0 | G29: 0 | H29: 0 | I29: 0 | J29: 0
A30: 701641.97 | B30: 52715.1 | C30: 7223 | D30: 84.2 | E30: 0 | F30: 0 | G30: 0 | H30: 0 | I30: 0 | J30: 0
A31: 511844.41 | B31: 68600.62 | C31: 3988 | D31: 85 | E31: 0 | F31: 0 | G31: 1 | H31: 0 | I31: 0 | J31: 1 | M31: RESIDUAL OUTPUT
A32: 537383.79 | B32: 63176.73 | C32: 2390 | D32: 87.5 | E32: 0 | F32: 0 | G32: 1 | H32: 0 | I32: 0 | J32: 1
A33: 500173.02 | B33: 44970.08 | C33: 2471 | D33: 87.6 | E33: 0 | F33: 0 | G33: 1 | H33: 0 | I33: 0 | J33: 1 | M33: Observation | N33: Predicted monthly_sales | O33: Residuals
A34: 427917.38 | B34: 69816.35 | C34: 971 | D34: 89.9 | E34: 0 | F34: 0 | G34: 1 | H34: 0 | I34: 0 | J34: 1 | M34: 1 | N34: 689614.62 | O34: -30781.996
A35: 641865.03 | B35: 54597.83 | C35: 9429 | D35: 83.3 | E35: 1 | F35: 0 | G35: 0 | H35: 0 | I35: 0 | J35: 1 | M35: 2 | N35: 692150.39 | O35: -57714.389
A36: 799477.76 | B36: 73771.91 | C36: 11695 | D36: 84.7 | E36: 1 | F36: 0 | G36: 0 | H36: 0 | I36: 0 | J36: 1 | M36: 3 | N36: 743132.47 | O36: -64410.412
A37: 798952.17 | B37: 74413.88 | C37: 9449 | D37: 92.1 | E37: 1 | F37: 0 | G37: 0 | H37: 0 | I37: 0 | J37: 1 | M37: 4 | N37: 747000.04 | O37: -88079.736
A38: 800979.78 | B38: 52483.77 | C38: 10453 | D38: 99 | E38: 1 | F38: 0 | G38: 0 | H38: 0 | I38: 0 | J38: 1 | M38: 5 | N38: 789087.65 | O38: -47746.211
A39: 820593.93 | B39: 75269.87 | C39: 8838 | D39: 83.1 | E39: 1 | F39: 0 | G39: 0 | H39: 0 | I39: 0 | J39: 0 | M39: 6 | N39: 777257.37 | O39: -15422.03
A40: 718330.53 | B40: 61245.41 | C40: 8156 | D40: 92.9 | E40: 1 | F40: 0 | G40: 0 | H40: 0 | I40: 0 | J40: 0 | M40: 7 | N40: 786018.33 | O40: 20597.21
...

Sheet Predictions_Residuals
A1: marketing_spend | B1: footfall | C1: inventory_availability_pct | D1: Region_North | E1: Region_South | F1: Region_East | G1: Store_Airport | H1: Store_HighStreet | I1: Store_Residential | J1: Actual monthly_sales | K1: Predicted_Sales | L1: Residual | M1: Absolute_Residual
A2: 79346.1 | B2: 9628 | C2: 99 | D2: 0 | E2: 0 | F2: 0 | G2: 0 | H2: 1 | I2: 0 | J2: 685379.08 | K2: =150574.3805 +(1.188357955*A2) +(33.85981294*B2) +(2961.270646*C2) +(-10576.28618*D2) +(1313.395721*E2) +(-18934.81748*F2) +(10756.80055*G2) +(-12295.38702*H2) +(-28871.87105*I2) -> 851738.64 | L2: =J2-K2 -> -166359.56 | M2: =ABS(L2) -> 166359.56
A3: 141540.29 | B3: 5400 | C3: 87 | D3: 0 | E3: 1 | F3: 0 | G3: 0 | H3: 0 | I3: 0 | J3: 627171.9 | K3: =150574.3805 +(1.188357955*A3) +(33.85981294*B3) +(2961.270646*C3) +(-10576.28618*D3) +(1313.395721*E3) +(-18934.81748*F3) +(10756.80055*G3) +(-12295.38702*H3) +(-28871.87105*I3) -> 760561.84 | L3: =J3-K3 -> -133389.94 | M3: =ABS(L3) -> 133389.94
A4: 138855.51 | B4: 5145 | C4: 88.2 | D4: 0 | E4: 0 | F4: 0 | G4: 0 | H4: 0 | I4: 1 | J4: 595467.6 | K4: =150574.3805 +(1.188357955*A4) +(33.85981294*B4) +(2961.270646*C4) +(-10576.28618*D4) +(1313.395721*E4) +(-18934.81748*F4) +(10756.80055*G4) +(-12295.38702*H4) +(-28871.87105*I4) -> 722105.37 | L4: =J4-K4 -> -126637.77 | M4: =ABS(L4) -> 126637.77
A5: 172415.52 | B5: 8927 | C5: 86.2 | D5: 0 | E5: 0 | F5: 0 | G5: 0 | H5: 0 | I5: 0 | J5: 800451.94 | K5: =150574.3805 +(1.188357955*A5) +(33.85981294*B5) +(2961.270646*C5) +(-10576.28618*D5) +(1313.395721*E5) +(-18934.81748*F5) +(10756.80055*G5) +(-12295.38702*H5) +(-28871.87105*I5) -> 912993.82 | L5: =J5-K5 -> -112541.88 | M5: =ABS(L5) -> 112541.88
A6: 54597.83 | B6: 9429 | C6: 83.3 | D6: 1 | E6: 0 | F6: 0 | G6: 0 | H6: 0 | I6: 1 | J6: 641865.03 | K6: =150574.3805 +(1.188357955*A6) +(33.85981294*B6) +(2961.270646*C6) +(-10576.28618*D6) +(1313.395721*E6) +(-18934.81748*F6) +(10756.80055*G6) +(-12295.38702*H6) +(-28871.87105*I6) -> 741946.01 | L6: =J6-K6 -> -100080.98 | M6: =ABS(L6) -> 100080.98
A7: 53015.46 | B7: 3279 | C7: 84.3 | D7: 0 | E7: 0 | F7: 0 | G7: 0 | H7: 1 | I7: 0 | J7: 463534.25 | K7: =150574.3805 +(1.188357955*A7) +(33.85981294*B7) +(2961.270646*C7) +(-10576.28618*D7) +(1313.395721*E7) +(-18934.81748*F7) +(10756.80055*G7) +(-12295.38702*H7) +(-28871.87105*I7) -> 561941.78 | L7: =J7-K7 -> -98407.529 | M7: =ABS(L7) -> 98407.529
A8: 46146.24 | B8: 5804 | C8: 86.9 | D8: 0 | E8: 1 | F8: 0 | G8: 0 | H8: 0 | I8: 1 | J8: 538376 | K8: =150574.3805 +(1.188357955*A8) +(33.85981294*B8) +(2961.270646*C8) +(-10576.28618*D8) +(1313.395721*E8) +(-18934.81748*F8) +(10756.80055*G8) +(-12295.38702*H8) +(-28871.87105*I8) -> 631710.93 | L8: =J8-K8 -> -93334.93 | M8: =ABS(L8) -> 93334.93
A9: 56856.63 | B9: 9431 | C9: 86.9 | D9: 0 | E9: 0 | F9: 1 | G9: 0 | H9: 0 | I9: 1 | J9: 658920.3 | K9: =150574.3805 +(1.188357955*A9) +(33.85981294*B9) +(2961.270646*C9) +(-10576.28618*D9) +(1313.395721*E9) +(-18934.81748*F9) +(10756.80055*G9) +(-12295.38702*H9) +(-28871.87105*I9) -> 747000.04 | L9: =J9-K9 -> -88079.735 | M9: =ABS(L9) -> 88079.735
A10: 46495.4 | B10: 9908 | C10: 89.4 | D10: 0 | E10: 0 | F10: 0 | G10: 0 | H10: 0 | I10: 0 | J10: 721079.35 | K10: =150574.3805 +(1.188357955*A10) +(33.85981294*B10) +(2961.270646*C10) +(-10576.28618*D10) +(1313.395721*E10) +(-18934.81748*F10) +(10756.80055*G10) +(-12295.38702*H10) +(-28871.87105*I10) -> 806048.18 | L10: =J10-K10 -> -84968.831 | M10: =ABS(L10) -> 84968.831
A11: 48752.92 | B11: 8052 | C11: 94.9 | D11: 0 | E11: 0 | F11: 1 | G11: 0 | H11: 0 | I11: 0 | J11: 660633.99 | K11: =150574.3805 +(1.188357955*A11) +(33.85981294*B11) +(2961.270646*C11) +(-10576.28618*D11) +(1313.395721*E11) +(-18934.81748*F11) +(10756.80055*G11) +(-12295.38702*H11) +(-28871.87105*I11) -> 743239.28 | L11: =J11-K11 -> -82605.291 | M11: =ABS(L11) -> 82605.291
A12: 56413.83 | B12: 8303 | C12: 93.6 | D12: 0 | E12: 0 | F12: 1 | G12: 0 | H12: 0 | I12: 0 | J12: 675917.63 | K12: =150574.3805 +(1.188357955*A12) +(33.85981294*B12) +(2961.270646*C12) +(-10576.28618*D12) +(1313.395721*E12) +(-18934.81748*F12) +(10756.80055*G12) +(-12295.38702*H12) +(-28871.87105*I12) -> 756992.35 | L12: =J12-K12 -> -81074.716 | M12: =ABS(L12) -> 81074.716
A13: 41657.64 | B13: 3135 | C13: 85.4 | D13: 0 | E13: 0 | F13: 0 | G13: 0 | H13: 0 | I13: 1 | J13: 449465.06 | K13: =150574.3805 +(1.188357955*A13) +(33.85981294*B13) +(2961.270646*C13) +(-10576.28618*D13) +(1313.395721*E13) +(-18934.81748*F13) +(10756.80055*G13) +(-12295.38702*H13) +(-28871.87105*I13) -> 530249.72 | L13: =J13-K13 -> -80784.664 | M13: =ABS(L13) -> 80784.664
... A321: 56737.3 | B321: 8300 | C321: 83.2 | D321: 0 | E321: 0 | F321: 1 | G321: 0 | H321: 0 | I321: 1 | J321: 813316.71 | K321: =150574.3805 +(1.188357955*A321) +(33.85981294*B321) +(2961.270646*C321) +(-10576.28618*D321) +(1313.395721*E321) +(-18934.81748*F321) +(10756.80055*G321) +(-12295.38702*H321) +(-28871.87105*I321) -> 697606.08 | L321: =J321-K321 -> 115710.63 | M321: =ABS(L321) -> 115710.63

Sheet Model_Comparison
A2: Model Name | B2: Variables Used | C2: R² | D2: Key Significant Variables (p < 0.05) | E2: Business Interpretation | F2: Limitations | G2: Final Verdict
A3: Simple Regression Model 1 | B3: monthly_sales ~ marketing_spend | C3: 0.167 | D3: marketing_spend | E3: Marketing spend has a positive impact on sales, but alone it explains only 16.7% of sales variation. Many other factors influence store performance. | F3: Ignores customer traffic, inventory levels, region, and store characteristics. | G3: Weak model; useful only for understanding marketing impact.
A5: Simple Regression Model 2 | B5: monthly_sales ~ footfall | C5: 0.736 | D5: footfall | E5: Footfall is strongly associated with monthly sales. Stores with higher customer traffic generally generate higher revenue. | F5: Does not account for operational or location-based factors. | G5: Strong predictor but incomplete model.
A7: Final Multiple Regression Model | B7: 3 Numerical Predictors + 3 Region Dummies + 3 Store Type Dummies | C7: 0.827 | D7: marketing_spend, footfall, inventory_availability_pct, Region_East, Store_Residential | E7: This model explains 82.7% of the variation in monthly sales. It captures both categorical and numerical independent variables, making it the most useful model for business decision-making. | F7: Regression identifies associations but cannot automatically prove causation. Some dummy variables are not statistically significant. External factors such as competition, economic conditions, and promotions are not included. | G7: Selected as the final model because it has the highest explanatory power and strongest business applicability.
